Workbook

Sheet Key
A1: Spreadsheet to calculate DIC, HCO3-, pCO2 and epCO2 (field)
A2: From GC measurement of ppm CO2 in Umeå
A3: Using vials 22ml (initially with N2, 5 mL streamwater added to give overpressure)
A4: Marcus W & Erin H, June 2015
A8: The following cells must be filled in those outlined in | E8: blue | F8: in the four worksheets.
A11: Sheet | B11: Variable | C11: Units | D11: Notes
A12: Volumes
B13: Bottle Nr
B14: Water volume incl, acid | C14: mL
B15: Headspace volume | C15: mL
B16: Sample volume | C16: mL
A18: DIC
B19: ppm CO2 from the GC | C19: ppm
A21: C speciation
B23: pH | D23: Stream pH
B24: Temp (field) | C24: C | D24: Streamwater temp
A26: CH4
B27: ppm CH4 from the GC | C27: ppm

Sheet Volumes
A1: Bottle Nr | B1: water vol (mL) | C1: headspace vol (mL) | D1: Sample vol (mL)
A3: DC4 2019-12-12 | B3: 5.1 | C3: 17 | D3: 5
A4: DC4 2019-11-20 | B4: 5.1 | C4: 17 | D4: 5
A5: DC4 2022-05-16 | B5: 5.1 | C5: 17 | D5: 5
A6: DC4 2021-05-25 | B6: 5.1 | C6: 17 | D6: 5
A7: DC4 2022-02-09 | B7: 5.1 | C7: 17 | D7: 5
A8: DC4 2020-11-03 | B8: 5.1 | C8: 17 | D8: 5
A9: DC4 2021-07-07 | B9: 5.1 | C9: 17 | D9: 5
A10: DC4 2021-04-29 | B10: 5.1 | C10: 17 | D10: 5
A11: DC4 2021-08-03 | B11: 5.1 | C11: 17 | D11: 5
A12: DC4 2022-05-06 | B12: 5.1 | C12: 17 | D12: 5
A13: DC4 2021-04-08 | B13: 5.1 | C13: 17 | D13: 5
A14: DC4 2021-06-21 | B14: 5.1 | C14: 17 | D14: 5
... A231: DC3 2021-01-20 | B231: 5.1 | C231: 17 | D231: 5

Sheet DIC
B1: Raw GC data | D1: Should be kept constant: 308.15 K and pH 2 | J1: R gas constant (L atm mol-1 K-1)
D2: T is the temperature of the sample when injecting in GC | J2: 0.0820578
B4: ppm | C4: atm | D4: K | E4: mol L-1 atm-1 | G4: mol L-1 | H4: Harned & Davis 1943; Weiss 1974 | I4: Harned & Scholes 1941 | J4: mol | K4: mol | L4: mol | M4: mol | N4: mol | O4: mol L-1 | P4: mg L-1 | Q4: mg L-1
A5: Bottle Nr | B5: CO2 | C5: CO2 | D5: T lab | E5: KH (lab) | F5: pH (lab) | G5: H+ | H5: K1 (lab) | I5: K2 (lab) | J5: CO2 gas | K5: H2CO3*(lab) | L5: HCO3- (lab) | M5: CO32- (lab) | N5: CO2 dis | O5: Total CO2 | P5: Total CO2 | Q5: DIC
A7: DC4 2019-12-12 | B7: 2929.1525 | C7: =B7/1000000 -> 0.0029291525 | D7: 308.15 | E7: =EXP(-58.0931+(90.5069*(100/D7))+(22.294*LN(D7/100))) -> 0.026462896 | F7: 2 | G7: =10^-F7 -> 0.01 | H7: =10^((-3404.71/D7)+14.8435-0.032786*D7) -> 4.9161123e-07 | I7: =10^((-2902.39/D7)+6.498-0.02379*D7) -> 5.6021457e-11 | J7: =(Volumes!B3+Volumes!C3)/1000*B7*(10^-6)/($J$2*D7) -> 2.5600723e-06 | K7: =(Volumes!B3/1000)*C7*E7*((Volumes!D3+Volumes!C3)/Volumes!C3/1000) -> 5.1159147e-10 | L7: =J7*(H7/1000*Volumes!B3)/(G7/1000*Volumes!B3) -> 1.2585603e-10 | M7: =L7*(I7/1000*Volumes!B3)/(G7/1000*Volumes!B3) -> 7.0506381e-19 | N7: =SUM(K7:M7) -> 6.374475e-10 | O7: =(N7+J7)*(1000/Volumes!D3) -> 0.00051214194 | P7: =O7*44.009*1000 -> 22.538855 | Q7: =P7/44.009*12.011 -> 6.1513368
A8: DC4 2019-11-20 | B8: 2045.2515 | C8: =B8/1000000 -> 0.0020452515 | D8: 308.15 | E8: =EXP(-58.0931+(90.5069*(100/D8))+(22.294*LN(D8/100))) -> 0.026462896 | F8: 2 | G8: =10^-F8 -> 0.01 | H8: =10^((-3404.71/D8)+14.8435-0.032786*D8) -> 4.9161123e-07 | I8: =10^((-2902.39/D8)+6.498-0.02379*D8) -> 5.6021457e-11 | J8: =(Volumes!B4+Volumes!C4)/1000*B8*(10^-6)/($J$2*D8) -> 1.7875448e-06 | K8: =(Volumes!B4/1000)*C8*E8*((Volumes!D4+Volumes!C4)/Volumes!C4/1000) -> 3.5721363e-10 | L8: =J8*(H8/1000*Volumes!B4)/(G8/1000*Volumes!B4) -> 8.7877712e-11 | M8: =L8*(I8/1000*Volumes!B4)/(G8/1000*Volumes!B4) -> 4.9230375e-19 | N8: =SUM(K8:M8) -> 4.4509134e-10 | O8: =(N8+J8)*(1000/Volumes!D4) -> 0.00035759799 | P8: =O8*44.009*1000 -> 15.73753 | Q8: =P8/44.009*12.011 -> 4.2951094
A9: DC4 2022-05-16 | B9: 1604 | C9: =B9/1000000 -> 0.001604 | D9: 308.15 | E9: =EXP(-58.0931+(90.5069*(100/D9))+(22.294*LN(D9/100))) -> 0.026462896 | F9: 2 | G9: =10^-F9 -> 0.01 | H9: =10^((-3404.71/D9)+14.8435-0.032786*D9) -> 4.9161123e-07 | I9: =10^((-2902.39/D9)+6.498-0.02379*D9) -> 5.6021457e-11 | J9: =(Volumes!B5+Volumes!C5)/1000*B9*(10^-6)/($J$2*D9) -> 1.4018921e-06 | K9: =(Volumes!B5/1000)*C9*E9*((Volumes!D5+Volumes!C5)/Volumes!C5/1000) -> 2.801468e-10 | L9: =J9*(H9/1000*Volumes!B5)/(G9/1000*Volumes!B5) -> 6.8918592e-11 | M9: =L9*(I9/1000*Volumes!B5)/(G9/1000*Volumes!B5) -> 3.8609199e-19 | N9: =SUM(K9:M9) -> 3.4906539e-10 | O9: =(N9+J9)*(1000/Volumes!D5) -> 0.00028044824 | P9: =O9*44.009*1000 -> 12.342247 | Q9: =P9/44.009*12.011 -> 3.3684638
A10: DC4 2021-05-25 | B10: 1815.4894 | C10: =B10/1000000 -> 0.0018154894 | D10: 308.15 | E10: =EXP(-58.0931+(90.5069*(100/D10))+(22.294*LN(D10/100))) -> 0.026462896 | F10: 2 | G10: =10^-F10 -> 0.01 | H10: =10^((-3404.71/D10)+14.8435-0.032786*D10) -> 4.9161123e-07 | I10: =10^((-2902.39/D10)+6.498-0.02379*D10) -> 5.6021457e-11 | J10: =(Volumes!B6+Volumes!C6)/1000*B10*(10^-6)/($J$2*D10) -> 1.5867333e-06 | K10: =(Volumes!B6/1000)*C10*E10*((Volumes!D6+Volumes!C6)/Volumes!C6/1000) -> 3.170845e-10 | L10: =J10*(H10/1000*Volumes!B6)/(G10/1000*Volumes!B6) -> 7.8005593e-11 | M10: =L10*(I10/1000*Volumes!B6)/(G10/1000*Volumes!B6) -> 4.369987e-19 | N10: =SUM(K10:M10) -> 3.9509009e-10 | O10: =(N10+J10)*(1000/Volumes!D6) -> 0.00031742568 | P10: =O10*44.009*1000 -> 13.969587 | Q10: =P10/44.009*12.011 -> 3.8125999
A11: DC4 2022-02-09 | B11: 7737 | C11: =B11/1000000 -> 0.007737 | D11: 308.15 | E11: =EXP(-58.0931+(90.5069*(100/D11))+(22.294*LN(D11/100))) -> 0.026462896 | F11: 2 | G11: =10^-F11 -> 0.01 | H11: =10^((-3404.71/D11)+14.8435-0.032786*D11) -> 4.9161123e-07 | I11: =10^((-2902.39/D11)+6.498-0.02379*D11) -> 5.6021457e-11 | J11: =(Volumes!B7+Volumes!C7)/1000*B11*(10^-6)/($J$2*D11) -> 6.7621193e-06 | K11: =(Volumes!B7/1000)*C11*E11*((Volumes!D7+Volumes!C7)/Volumes!C7/1000) -> 1.3513066e-09 | L11: =J11*(H11/1000*Volumes!B7)/(G11/1000*Volumes!B7) -> 3.3243338e-10 | M11: =L11*(I11/1000*Volumes!B7)/(G11/1000*Volumes!B7) -> 1.8623402e-18 | N11: =SUM(K11:M11) -> 1.68374e-09 | O11: =(N11+J11)*(1000/Volumes!D7) -> 0.0013527606 | P11: =O11*44.009*1000 -> 59.533642 | Q11: =P11/44.009*12.011 -> 16.248008
A12: DC4 2020-11-03 | B12: 1345.2139 | C12: =B12/1000000 -> 0.0013452139 | D12: 308.15 | E12: =EXP(-58.0931+(90.5069*(100/D12))+(22.294*LN(D12/100))) -> 0.026462896 | F12: 2 | G12: =10^-F12 -> 0.01 | H12: =10^((-3404.71/D12)+14.8435-0.032786*D12) -> 4.9161123e-07 | I12: =10^((-2902.39/D12)+6.498-0.02379*D12) -> 5.6021457e-11 | J12: =(Volumes!B8+Volumes!C8)/1000*B12*(10^-6)/($J$2*D12) -> 1.1757137e-06 | K12: =(Volumes!B8/1000)*C12*E12*((Volumes!D8+Volumes!C8)/Volumes!C8/1000) -> 2.3494848e-10 | L12: =J12*(H12/1000*Volumes!B8)/(G12/1000*Volumes!B8) -> 5.7799405e-11 | M12: =L12*(I12/1000*Volumes!B8)/(G12/1000*Volumes!B8) -> 3.2380069e-19 | N12: =SUM(K12:M12) -> 2.9274788e-10 | O12: =(N12+J12)*(1000/Volumes!D8) -> 0.00023520128 | P12: =O12*44.009*1000 -> 10.350973 | Q12: =P12/44.009*12.011 -> 2.8250026
A13: DC4 2021-07-07 | B13: 9288.7035 | C13: =B13/1000000 -> 0.0092887035 | D13: 308.15 | E13: =EXP(-58.0931+(90.5069*(100/D13))+(22.294*LN(D13/100))) -> 0.026462896 | F13: 2 | G13: =10^-F13 -> 0.01 | H13: =10^((-3404.71/D13)+14.8435-0.032786*D13) -> 4.9161123e-07 | I13: =10^((-2902.39/D13)+6.498-0.02379*D13) -> 5.6021457e-11 | J13: =(Volumes!B9+Volumes!C9)/1000*B13*(10^-6)/($J$2*D13) -> 8.1183044e-06 | K13: =(Volumes!B9/1000)*C13*E13*((Volumes!D9+Volumes!C9)/Volumes!C9/1000) -> 1.6223196e-09 | L13: =J13*(H13/1000*Volumes!B9)/(G13/1000*Volumes!B9) -> 3.9910496e-10 | M13: =L13*(I13/1000*Volumes!B9)/(G13/1000*Volumes!B9) -> 2.2358442e-18 | N13: =SUM(K13:M13) -> 2.0214245e-09 | O13: =(N13+J13)*(1000/Volumes!D9) -> 0.0016240652 | P13: =O13*44.009*1000 -> 71.473484 | Q13: =P13/44.009*12.011 -> 19.506647
A14: DC4 2021-04-29 | B14: 1303.8961 | C14: =B14/1000000 -> 0.0013038961 | D14: 308.15 | E14: =EXP(-58.0931+(90.5069*(100/D14))+(22.294*LN(D14/100))) -> 0.026462896 | F14: 2 | G14: =10^-F14 -> 0.01 | H14: =10^((-3404.71/D14)+14.8435-0.032786*D14) -> 4.9161123e-07 | I14: =10^((-2902.39/D14)+6.498-0.02379*D14) -> 5.6021457e-11 | J14: =(Volumes!B10+Volumes!C10)/1000*B14*(10^-6)/($J$2*D14) -> 1.139602e-06 | K14: =(Volumes!B10/1000)*C14*E14*((Volumes!D10+Volumes!C10)/Volumes!C10/1000) -> 2.2773211e-10 | L14: =J14*(H14/1000*Volumes!B10)/(G14/1000*Volumes!B10) -> 5.6024115e-11 | M14: =L14*(I14/1000*Volumes!B10)/(G14/1000*Volumes!B10) -> 3.1385526e-19 | N14: =SUM(K14:M14) -> 2.8375623e-10 | O14: =(N14+J14)*(1000/Volumes!D10) -> 0.00022797715 | P14: =O14*44.009*1000 -> 10.033047 | Q14: =P14/44.009*12.011 -> 2.7382336
A15: DC4 2021-08-03 | B15: 2022.0716 | C15: =B15/1000000 -> 0.0020220716 | D15: 308.15 | E15: =EXP(-58.0931+(90.5069*(100/D15))+(22.294*LN(D15/100))) -> 0.026462896 | F15: 2 | G15: =10^-F15 -> 0.01 | H15: =10^((-3404.71/D15)+14.8435-0.032786*D15) -> 4.9161123e-07 | I15: =10^((-2902.39/D15)+6.498-0.02379*D15) -> 5.6021457e-11 | J15: =(Volumes!B11+Volumes!C11)/1000*B15*(10^-6)/($J$2*D15) -> 1.7672857e-06 | K15: =(Volumes!B11/1000)*C15*E15*((Volumes!D11+Volumes!C11)/Volumes!C11/1000) -> 3.5316515e-10 | L15: =J15*(H15/1000*Volumes!B11)/(G15/1000*Volumes!B11) -> 8.688175e-11 | M15: =L15*(I15/1000*Volumes!B11)/(G15/1000*Volumes!B11) -> 4.8672423e-19 | N15: =SUM(K15:M15) -> 4.400469e-10 | O15: =(N15+J15)*(1000/Volumes!D11) -> 0.00035354515 | P15: =O15*44.009*1000 -> 15.559169 | Q15: =P15/44.009*12.011 -> 4.2464308
A16: DC4 2022-05-06 | B16: 1873 | C16: =B16/1000000 -> 0.001873 | D16: 308.15 | E16: =EXP(-58.0931+(90.5069*(100/D16))+(22.294*LN(D16/100))) -> 0.026462896 | F16: 2 | G16: =10^-F16 -> 0.01 | H16: =10^((-3404.71/D16)+14.8435-0.032786*D16) -> 4.9161123e-07 | I16: =10^((-2902.39/D16)+6.498-0.02379*D16) -> 5.6021457e-11 | J16: =(Volumes!B12+Volumes!C12)/1000*B16*(10^-6)/($J$2*D16) -> 1.6369975e-06 | K16: =(Volumes!B12/1000)*C16*E16*((Volumes!D12+Volumes!C12)/Volumes!C12/1000) -> 3.2712903e-10 | L16: =J16*(H16/1000*Volumes!B12)/(G16/1000*Volumes!B12) -> 8.0476635e-11 | M16: =L16*(I16/1000*Volumes!B12)/(G16/1000*Volumes!B12) -> 4.5084183e-19 | N16: =SUM(K16:M16) -> 4.0760566e-10 | O16: =(N16+J16)*(1000/Volumes!D12) -> 0.00032748102 | P16: =O16*44.009*1000 -> 14.412112 | Q16: =P16/44.009*12.011 -> 3.9333745
A17: DC4 2021-04-08 | B17: 1689.9322 | C17: =B17/1000000 -> 0.0016899322 | D17: 308.15 | E17: =EXP(-58.0931+(90.5069*(100/D17))+(22.294*LN(D17/100))) -> 0.026462896 | F17: 2 | G17: =10^-F17 -> 0.01 | H17: =10^((-3404.71/D17)+14.8435-0.032786*D17) -> 4.9161123e-07 | I17: =10^((-2902.39/D17)+6.498-0.02379*D17) -> 5.6021457e-11 | J17: =(Volumes!B13+Volumes!C13)/1000*B17*(10^-6)/($J$2*D17) -> 1.4769966e-06 | K17: =(Volumes!B13/1000)*C17*E17*((Volumes!D13+Volumes!C13)/Volumes!C13/1000) -> 2.9515529e-10 | L17: =J17*(H17/1000*Volumes!B13)/(G17/1000*Volumes!B13) -> 7.2610813e-11 | M17: =L17*(I17/1000*Volumes!B13)/(G17/1000*Volumes!B13) -> 4.0677636e-19 | N17: =SUM(K17:M17) -> 3.6776611e-10 | O17: =(N17+J17)*(1000/Volumes!D13) -> 0.00029547288 | P17: =O17*44.009*1000 -> 13.003466 | Q17: =P17/44.009*12.011 -> 3.5489247
A18: DC4 2021-06-21 | B18: 1335.1108 | C18: =B18/1000000 -> 0.0013351108 | D18: 308.15 | E18: =EXP(-58.0931+(90.5069*(100/D18))+(22.294*LN(D18/100))) -> 0.026462896 | F18: 2 | G18: =10^-F18 -> 0.01 | H18: =10^((-3404.71/D18)+14.8435-0.032786*D18) -> 4.9161123e-07 | I18: =10^((-2902.39/D18)+6.498-0.02379*D18) -> 5.6021457e-11 | J18: =(Volumes!B14+Volumes!C14)/1000*B18*(10^-6)/($J$2*D18) -> 1.1668836e-06 | K18: =(Volumes!B14/1000)*C18*E18*((Volumes!D14+Volumes!C14)/Volumes!C14/1000) -> 2.3318393e-10 | L18: =J18*(H18/1000*Volumes!B14)/(G18/1000*Volumes!B14) -> 5.7365309e-11 | M18: =L18*(I18/1000*Volumes!B14)/(G18/1000*Volumes!B14) -> 3.2136882e-19 | N18: =SUM(K18:M18) -> 2.9054924e-10 | O18: =(N18+J18)*(1000/Volumes!D14) -> 0.00023343483 | P18: =O18*44.009*1000 -> 10.273234 | Q18: =P18/44.009*12.011 -> 2.8037858
... A235: DC3 2021-01-20 | B235: 914.68063 | C235: =B235/1000000 -> 0.00091468063 | D235: 308.15 | E235: =EXP(-58.0931+(90.5069*(100/D235))+(22.294*LN(D235/100))) -> 0.026462896 | F235: 2 | G235: =10^-F235 -> 0.01 | H235: =10^((-3404.71/D235)+14.8435-0.032786*D235) -> 4.9161123e-07 | I235: =10^((-2902.39/D235)+6.498-0.02379*D235) -> 5.6021457e-11 | J235: =(Volumes!B231+Volumes!C231)/1000*B235*(10^-6)/($J$2*D235) -> 7.9942866e-07 | K235: =(Volumes!B231/1000)*C235*E235*((Volumes!D231+Volumes!C231)/Volumes!C231/1000) -> 1.5975365e-10 | L235: =J235*(H235/1000*Volumes!B231)/(G235/1000*Volumes!B231) -> 3.9300811e-11 | M235: =L235*(I235/1000*Volumes!B231)/(G235/1000*Volumes!B231) -> 2.2016887e-19 | N235: =SUM(K235:M235) -> 1.9905446e-10 | O235: =(N235+J235)*(1000/Volumes!D231) -> 0.00015992554 | P235: =O235*44.009*1000 -> 7.0381632 | Q235: =P235/44.009*12.011 -> 1.9208657

Sheet C-speciation
G1: pK1 | H1: 6.352 | I1: K1 | J1: =10^-H1 -> 4.4463127e-07 | L1: ideal gas constant | M1: UNITS | P1: ppm | Q1: uatm
B2: Field pH and temp | G2: pK2 | H2: 10.33 | I2: K2 | J2: =10^-H2 -> 4.6773514e-11 | L2: R | M2: 0.082057 | N2: equil atm pCO2 | P2: 400 | Q2: =P2 -> 400
G3: (Note these pk values are NOT currently used - use instead temperature dependant equations as seen below)
B5: pH units | C5: mol L-1 | D5: mol L-1 | E5: C | F5: K | G5: From Weiss 1974 | H5: Harned & Davis 1943; Weiss 1974 | I5: Harned & Scholes 1941 | J5: mol L-1 | K5: mol L-1 | L5: mol L-1 | M5: mol L-1 | N5: uatm | O5: - | P5: mg L-1
A6: Serial Nr | B6: pH (lab) | C6: H+ (lab) | D6: CTOT (in orig water sample) | E6: T (field) | F6: T (field) | G6: KH (field) | H6: K1 (field) | I6: K2 (field) | J6: H2CO3* (field) | K6: HCO3- (field) | L6: CO32- (field) | M6: CTOT (field, modeled) | N6: pCO2 (field, modeled) | O6: epCO2 | P6: CO2-C
A8: DC4 2019-12-12 | B8: 4.11 | C8: =10^-B8 -> 7.7624712e-05 | D8: =DIC!O7 -> 0.00051214194 | E8: 2 | F8: =E8+273.15 -> 275.15 | G8: =EXP(-58.0931+(90.5069*(100/F8))+(22.294*LN(F8/100))) -> 0.071743773 | H8: =10^((-3404.71/F8)+14.8435-0.032786*F8) -> 2.8081346e-07 | I8: =10^((-2902.39/F8)+6.498-0.02379*F8) -> 2.5339014e-11 | J8: =D8/(1+(H8/C8)+(H8*I8/C8^2)) -> 0.0005102959 | K8: =J8*H8/C8 -> 1.8460353e-06 | L8: =K8*I8/C8 -> 6.0260082e-13 | M8: =SUM(J8:L8) -> 0.00051214194 | N8: =J8/G8*1000000 -> 7112.7554 | O8: =N8/$Q$2 -> 17.781888 | P8: =J8*1000*12.01 -> 6.1286538
A9: DC4 2019-11-20 | B9: 4.07 | C9: =10^-B9 -> 8.5113804e-05 | D9: =DIC!O8 -> 0.00035759799 | E9: 2 | F9: =E9+273.15 -> 275.15 | G9: =EXP(-58.0931+(90.5069*(100/F9))+(22.294*LN(F9/100))) -> 0.071743773 | H9: =10^((-3404.71/F9)+14.8435-0.032786*F9) -> 2.8081346e-07 | I9: =10^((-2902.39/F9)+6.498-0.02379*F9) -> 2.5339014e-11 | J9: =D9/(1+(H9/C9)+(H9*I9/C9^2)) -> 0.00035642205 | K9: =J9*H9/C9 -> 1.1759328e-06 | L9: =K9*I9/C9 -> 3.5008396e-13 | M9: =SUM(J9:L9) -> 0.00035759799 | N9: =J9/G9*1000000 -> 4967.9859 | O9: =N9/$Q$2 -> 12.419965 | P9: =J9*1000*12.01 -> 4.2806289
A10: DC4 2022-05-16 | B10: 4.28 | C10: =10^-B10 -> 5.2480746e-05 | D10: =DIC!O9 -> 0.00028044824 | E10: 8.5362292 | F10: =E10+273.15 -> 281.68623 | G10: =EXP(-58.0931+(90.5069*(100/F10))+(22.294*LN(F10/100))) -> 0.056443693 | H10: =10^((-3404.71/F10)+14.8435-0.032786*F10) -> 3.3208323e-07 | I10: =10^((-2902.39/F10)+6.498-0.02379*F10) -> 3.112125e-11 | J10: =D10/(1+(H10/C10)+(H10*I10/C10^2)) -> 0.0002786848 | K10: =J10*H10/C10 -> 1.7634381e-06 | L10: =K10*I10/C10 -> 1.0457244e-12 | M10: =SUM(J10:L10) -> 0.00028044824 | N10: =J10/G10*1000000 -> 4937.3948 | O10: =N10/$Q$2 -> 12.343487 | P10: =J10*1000*12.01 -> 3.3470044
A11: DC4 2021-05-25 | B11: 4.1 | C11: =10^-B11 -> 7.9432823e-05 | D11: =DIC!O10 -> 0.00031742568 | E11: 8.4494479 | F11: =E11+273.15 -> 281.59945 | G11: =EXP(-58.0931+(90.5069*(100/F11))+(22.294*LN(F11/100))) -> 0.056615111 | H11: =10^((-3404.71/F11)+14.8435-0.032786*F11) -> 3.314113e-07 | I11: =10^((-2902.39/F11)+6.498-0.02379*F11) -> 3.1041754e-11 | J11: =D11/(1+(H11/C11)+(H11*I11/C11^2)) -> 0.00031610682 | K11: =J11*H11/C11 -> 1.3188675e-06 | L11: =K11*I11/C11 -> 5.1540357e-13 | M11: =SUM(J11:L11) -> 0.00031742568 | N11: =J11/G11*1000000 -> 5583.4354 | O11: =N11/$Q$2 -> 13.958589 | P11: =J11*1000*12.01 -> 3.7964429
A12: DC4 2022-02-09 | B12: 4.29 | C12: =10^-B12 -> 5.1286138e-05 | D12: =DIC!O11 -> 0.0013527606 | E12: 2 | F12: =E12+273.15 -> 275.15 | G12: =EXP(-58.0931+(90.5069*(100/F12))+(22.294*LN(F12/100))) -> 0.071743773 | H12: =10^((-3404.71/F12)+14.8435-0.032786*F12) -> 2.8081346e-07 | I12: =10^((-2902.39/F12)+6.498-0.02379*F12) -> 2.5339014e-11 | J12: =D12/(1+(H12/C12)+(H12*I12/C12^2)) -> 0.001345394 | K12: =J12*H12/C12 -> 7.3666055e-06 | L12: =K12*I12/C12 -> 3.6396291e-12 | M12: =SUM(J12:L12) -> 0.0013527606 | N12: =J12/G12*1000000 -> 18752.764 | O12: =N12/$Q$2 -> 46.881909 | P12: =J12*1000*12.01 -> 16.158182
A13: DC4 2020-11-03 | B13: 3.93 | C13: =10^-B13 -> 0.00011748976 | D13: =DIC!O12 -> 0.00023520128 | E13: 2 | F13: =E13+273.15 -> 275.15 | G13: =EXP(-58.0931+(90.5069*(100/F13))+(22.294*LN(F13/100))) -> 0.071743773 | H13: =10^((-3404.71/F13)+14.8435-0.032786*F13) -> 2.8081346e-07 | I13: =10^((-2902.39/F13)+6.498-0.02379*F13) -> 2.5339014e-11 | J13: =D13/(1+(H13/C13)+(H13*I13/C13^2)) -> 0.00023464047 | K13: =J13*H13/C13 -> 5.6081657e-07 | L13: =K13*I13/C13 -> 1.209513e-13 | M13: =SUM(J13:L13) -> 0.00023520128 | N13: =J13/G13*1000000 -> 3270.5343 | O13: =N13/$Q$2 -> 8.1763357 | P13: =J13*1000*12.01 -> 2.818032
A14: DC4 2021-07-07 | B14: 3.97 | C14: =10^-B14 -> 0.00010715193 | D14: =DIC!O13 -> 0.0016240652 | E14: 17.422917 | F14: =E14+273.15 -> 290.57292 | G14: =EXP(-58.0931+(90.5069*(100/F14))+(22.294*LN(F14/100))) -> 0.042226907 | H14: =10^((-3404.71/F14)+14.8435-0.032786*F14) -> 3.9769058e-07 | I14: =10^((-2902.39/F14)+6.498-0.02379*F14) -> 3.9514999e-11 | J14: =D14/(1+(H14/C14)+(H14*I14/C14^2)) -> 0.0016180598 | K14: =J14*H14/C14 -> 6.0053715e-06 | L14: =K14*I14/C14 -> 2.2146334e-12 | M14: =SUM(J14:L14) -> 0.0016240652 | N14: =J14/G14*1000000 -> 38318.217 | O14: =N14/$Q$2 -> 95.795542 | P14: =J14*1000*12.01 -> 19.432898
A15: DC4 2021-04-29 | B15: 4.17 | C15: =10^-B15 -> 6.7608298e-05 | D15: =DIC!O14 -> 0.00022797715 | E15: 2 | F15: =E15+273.15 -> 275.15 | G15: =EXP(-58.0931+(90.5069*(100/F15))+(22.294*LN(F15/100))) -> 0.071743773 | H15: =10^((-3404.71/F15)+14.8435-0.032786*F15) -> 2.8081346e-07 | I15: =10^((-2902.39/F15)+6.498-0.02379*F15) -> 2.5339014e-11 | J15: =D15/(1+(H15/C15)+(H15*I15/C15^2)) -> 0.00022703416 | K15: =J15*H15/C15 -> 9.4299443e-07 | L15: =K15*I15/C15 -> 3.5342628e-13 | M15: =SUM(J15:L15) -> 0.00022797715 | N15: =J15/G15*1000000 -> 3164.5138 | O15: =N15/$Q$2 -> 7.9112845 | P15: =J15*1000*12.01 -> 2.7266802
A16: DC4 2021-08-03 | B16: 3.99 | C16: =10^-B16 -> 0.0001023293 | D16: =DIC!O15 -> 0.00035354515 | E16: 12.364583 | F16: =E16+273.15 -> 285.51458 | G16: =EXP(-58.0931+(90.5069*(100/F16))+(22.294*LN(F16/100))) -> 0.049569384 | H16: =10^((-3404.71/F16)+14.8435-0.032786*F16) -> 3.6124257e-07 | I16: =10^((-2902.39/F16)+6.498-0.02379*F16) -> 3.468469e-11 | J16: =D16/(1+(H16/C16)+(H16*I16/C16^2)) -> 0.00035230146 | K16: =J16*H16/C16 -> 1.2436935e-06 | L16: =K16*I16/C16 -> 4.2155202e-13 | M16: =SUM(J16:L16) -> 0.00035354515 | N16: =J16/G16*1000000 -> 7107.239 | O16: =N16/$Q$2 -> 17.768097 | P16: =J16*1000*12.01 -> 4.2311405
A17: DC4 2022-05-06 | B17: 4.37 | C17: =10^-B17 -> 4.2657952e-05 | D17: =DIC!O16 -> 0.00032748102 | E17: 2 | F17: =E17+273.15 -> 275.15 | G17: =EXP(-58.0931+(90.5069*(100/F17))+(22.294*LN(F17/100))) -> 0.071743773 | H17: =10^((-3404.71/F17)+14.8435-0.032786*F17) -> 2.8081346e-07 | I17: =10^((-2902.39/F17)+6.498-0.02379*F17) -> 2.5339014e-11 | J17: =D17/(1+(H17/C17)+(H17*I17/C17^2)) -> 0.00032533934 | K17: =J17*H17/C17 -> 2.1416796e-06 | L17: =K17*I17/C17 -> 1.2721673e-12 | M17: =SUM(J17:L17) -> 0.00032748102 | N17: =J17/G17*1000000 -> 4534.7397 | O17: =N17/$Q$2 -> 11.336849 | P17: =J17*1000*12.01 -> 3.9073254
A18: DC4 2021-04-08 | B18: 4.1 | C18: =10^-B18 -> 7.9432823e-05 | D18: =DIC!O17 -> 0.00029547288 | E18: 2 | F18: =E18+273.15 -> 275.15 | G18: =EXP(-58.0931+(90.5069*(100/F18))+(22.294*LN(F18/100))) -> 0.071743773 | H18: =10^((-3404.71/F18)+14.8435-0.032786*F18) -> 2.8081346e-07 | I18: =10^((-2902.39/F18)+6.498-0.02379*F18) -> 2.5339014e-11 | J18: =D18/(1+(H18/C18)+(H18*I18/C18^2)) -> 0.00029443199 | K18: =J18*H18/C18 -> 1.0408854e-06 | L18: =K18*I18/C18 -> 3.3204171e-13 | M18: =SUM(J18:L18) -> 0.00029547288 | N18: =J18/G18*1000000 -> 4103.938 | O18: =N18/$Q$2 -> 10.259845 | P18: =J18*1000*12.01 -> 3.5361282
A19: DC4 2021-06-21 | B19: 4.08 | C19: =10^-B19 -> 8.3176377e-05 | D19: =DIC!O18 -> 0.00023343483 | E19: 11.219687 | F19: =E19+273.15 -> 284.36969 | G19: =EXP(-58.0931+(90.5069*(100/F19))+(22.294*LN(F19/100))) -> 0.051491729 | H19: =10^((-3404.71/F19)+14.8435-0.032786*F19) -> 3.526348e-07 | I19: =10^((-2902.39/F19)+6.498-0.02379*F19) -> 3.3608403e-11 | J19: =D19/(1+(H19/C19)+(H19*I19/C19^2)) -> 0.00023244934 | K19: =J19*H19/C19 -> 9.8549285e-07 | L19: =K19*I19/C19 -> 3.9820009e-13 | M19: =SUM(J19:L19) -> 0.00023343483 | N19: =J19/G19*1000000 -> 4514.3044 | O19: =N19/$Q$2 -> 11.285761 | P19: =J19*1000*12.01 -> 2.7917166
... A59: DC1 2021-05-07 | B59: 4.96 | C59: =10^-B59 -> 1.0964782e-05 | D59: =DIC!O58 -> 0.00010272694 | E59: 2 | F59: =E59+273.15 -> 275.15 | G59: =EXP(-58.0931+(90.5069*(100/F59))+(22.294*LN(F59/100))) -> 0.071743773 | H59: =10^((-3404.71/F59)+14.8435-0.032786*F59) -> 2.8081346e-07 | I59: =10^((-2902.39/F59)+6.498-0.02379*F59) -> 2.5339014e-11 | J59: =D59/(1+(H59/C59)+(H59*I59/C59^2)) -> 0.00010016174 | K59: =J59*H59/C59 -> 2.5651914e-06 | L59: =K59*I59/C59 -> 5.9280177e-12 | M59: =SUM(J59:L59) -> 0.00010272694 | N59: =J59/G59*1000000 -> 1396.1036 | O59: =N59/$Q$2 -> 3.490259 | P59: =J59*1000*12.01 -> 1.2029425
A60: DC1 2024-03-13 | B60: NA | C60: =10^-B60 -> #VALUE! | D60: =DIC!O59 -> 0.00032363447 | E60: 2 | F60: =E60+273.15 -> 275.15 | G60: =EXP(-58.0931+(90.5069*(100/F60))+(22.294*LN(F60/100))) -> 0.071743773 | H60: =10^((-3404.71/F60)+14.8435-0.032786*F60) -> 2.8081346e-07 | I60: =10^((-2902.39/F60)+6.498-0.02379*F60) -> 2.5339014e-11 | J60: =D60/(1+(H60/C60)+(H60*I60/C60^2)) -> #VALUE! | K60: =J60*H60/C60 -> #VALUE! | L60: =K60*I60/C60 -> #VALUE! | M60: =SUM(J60:L60) -> #VALUE! | N60: =J60/G60*1000000 -> #VALUE! | O60: =N60/$Q$2 -> #VALUE! | P60: =J60*1000*12.01 -> #VALUE!
A61: DC1 2020-11-03 | B61: 4.6 | C61: =10^-B61 -> 2.5118864e-05 | D61: =DIC!O60 -> 0.0001575282 | E61: 2 | F61: =E61+273.15 -> 275.15 | G61: =EXP(-58.0931+(90.5069*(100/F61))+(22.294*LN(F61/100))) -> 0.071743773 | H61: =10^((-3404.71/F61)+14.8435-0.032786*F61) -> 2.8081346e-07 | I61: =10^((-2902.39/F61)+6.498-0.02379*F61) -> 2.5339014e-11 | J61: =D61/(1+(H61/C61)+(H61*I61/C61^2)) -> 0.0001557866 | K61: =J61*H61/C61 -> 1.7415984e-06 | L61: =K61*I61/C61 -> 1.7568623e-12 | M61: =SUM(J61:L61) -> 0.0001575282 | N61: =J61/G61*1000000 -> 2171.4302 | O61: =N61/$Q$2 -> 5.4285756 | P61: =J61*1000*12.01 -> 1.870997
A62: DC1 2020-05-13 | B62: 4.99 | C62: =10^-B62 -> 1.023293e-05 | D62: =DIC!O61 -> 9.905017e-05 | E62: 8.9725417 | F62: =E62+273.15 -> 282.12254 | G62: =EXP(-58.0931+(90.5069*(100/F62))+(22.294*LN(F62/100))) -> 0.055593035 | H62: =10^((-3404.71/F62)+14.8435-0.032786*F62) -> 3.3545541e-07 | I62: =10^((-2902.39/F62)+6.498-0.02379*F62) -> 3.1521878e-11 | J62: =D62/(1+(H62/C62)+(H62*I62/C62^2)) -> 9.5906169e-05 | K62: =J62*H62/C62 -> 3.1439914e-06 | L62: =K62*I62/C62 -> 9.6848617e-12 | M62: =SUM(J62:L62) -> 9.905017e-05 | N62: =J62/G62*1000000 -> 1725.1472 | O62: =N62/$Q$2 -> 4.312868 | P62: =J62*1000*12.01 -> 1.1518331
A63: DC1 2021-11-10 | B63: 5.19 | C63: =10^-B63 -> 6.4565423e-06 | D63: =DIC!O62 -> 0.00013730692 | E63: 2 | F63: =E63+273.15 -> 275.15 | G63: =EXP(-58.0931+(90.5069*(100/F63))+(22.294*LN(F63/100))) -> 0.071743773 | H63: =10^((-3404.71/F63)+14.8435-0.032786*F63) -> 2.8081346e-07 | I63: =10^((-2902.39/F63)+6.498-0.02379*F63) -> 2.5339014e-11 | J63: =D63/(1+(H63/C63)+(H63*I63/C63^2)) -> 0.00013158394 | K63: =J63*H63/C63 -> 5.7229614e-06 | L63: =K63*I63/C63 -> 2.246004e-11 | M63: =SUM(J63:L63) -> 0.00013730692 | N63: =J63/G63*1000000 -> 1834.0817 | O63: =N63/$Q$2 -> 4.5852043 | P63: =J63*1000*12.01 -> 1.5803231
A64: DC1 2019-04-21 | B64: 4.55 | C64: =10^-B64 -> 2.8183829e-05 | D64: =DIC!O63 -> 0.00020185321 | E64: 2 | F64: =E64+273.15 -> 275.15 | G64: =EXP(-58.0931+(90.5069*(100/F64))+(22.294*LN(F64/100))) -> 0.071743773 | H64: =10^((-3404.71/F64)+14.8435-0.032786*F64) -> 2.8081346e-07 | I64: =10^((-2902.39/F64)+6.498-0.02379*F64) -> 2.5339014e-11 | J64: =D64/(1+(H64/C64)+(H64*I64/C64^2)) -> 0.00019986186 | K64: =J64*H64/C64 -> 1.9913512e-06 | L64: =K64*I64/C64 -> 1.7903484e-12 | M64: =SUM(J64:L64) -> 0.00020185321 | N64: =J64/G64*1000000 -> 2785.7729 | O64: =N64/$Q$2 -> 6.9644323 | P64: =J64*1000*12.01 -> 2.4003409
A65: DC1 2022-06-21 | B65: 5.21 | C65: =10^-B65 -> 6.16595e-06 | D65: =DIC!O64 -> 0.00014092349 | E65: 11.219687 | F65: =E65+273.15 -> 284.36969 | G65: =EXP(-58.0931+(90.5069*(100/F65))+(22.294*LN(F65/100))) -> 0.051491729 | H65: =10^((-3404.71/F65)+14.8435-0.032786*F65) -> 3.526348e-07 | I65: =10^((-2902.39/F65)+6.498-0.02379*F65) -> 3.3608403e-11 | J65: =D65/(1+(H65/C65)+(H65*I65/C65^2)) -> 0.00013329994 | K65: =J65*H65/C65 -> 7.6235124e-06 | L65: =K65*I65/C65 -> 4.1553057e-11 | M65: =SUM(J65:L65) -> 0.00014092349 | N65: =J65/G65*1000000 -> 2588.7641 | O65: =N65/$Q$2 -> 6.4719102 | P65: =J65*1000*12.01 -> 1.6009322
A66: DC1 2022-09-12 | B66: 5.82 | C66: =10^-B66 -> 1.5135612e-06 | D66: =DIC!O65 -> 0.00012483793 | E66: 9.7789583 | F66: =E66+273.15 -> 282.92896 | G66: =EXP(-58.0931+(90.5069*(100/F66))+(22.294*LN(F66/100))) -> 0.054068629 | H66: =10^((-3404.71/F66)+14.8435-0.032786*F66) -> 3.4165905e-07 | I66: =10^((-2902.39/F66)+6.498-0.02379*F66) -> 3.2266352e-11 | J66: =D66/(1+(H66/C66)+(H66*I66/C66^2)) -> 0.00010184726 | K66: =J66*H66/C66 -> 2.2990177e-05 | L66: =K66*I66/C66 -> 4.9010843e-10 | M66: =SUM(J66:L66) -> 0.00012483793 | N66: =J66/G66*1000000 -> 1883.6665 | O66: =N66/$Q$2 -> 4.7091663 | P66: =J66*1000*12.01 -> 1.2231857
A67: DC1 2020-08-24 | B67: 5.14 | C67: =10^-B67 -> 7.2443596e-06 | D67: =DIC!O66 -> 0.00023399766 | E67: 9.7107708 | F67: =E67+273.15 -> 282.86077 | G67: =EXP(-58.0931+(90.5069*(100/F67))+(22.294*LN(F67/100))) -> 0.05419518 | H67: =10^((-3404.71/F67)+14.8435-0.032786*F67) -> 3.4113605e-07 | I67: =10^((-2902.39/F67)+6.498-0.02379*F67) -> 3.2203207e-11 | J67: =D67/(1+(H67/C67)+(H67*I67/C67^2)) -> 0.00022347424 | K67: =J67*H67/C67 -> 1.0523376e-05 | L67: =K67*I67/C67 -> 4.6779352e-11 | M67: =SUM(J67:L67) -> 0.00023399766 | N67: =J67/G67*1000000 -> 4123.5077 | O67: =N67/$Q$2 -> 10.308769 | P67: =J67*1000*12.01 -> 2.6839256
A68: DC1 2019-06-18 | B68: 4.86 | C68: =10^-B68 -> 1.3803843e-05 | D68: =DIC!O67 -> 0.00024806423 | E68: 11.616354 | F68: =E68+273.15 -> 284.76635 | G68: =EXP(-58.0931+(90.5069*(100/F68))+(22.294*LN(F68/100))) -> 0.050813574 | H68: =10^((-3404.71/F68)+14.8435-0.032786*F68) -> 3.556294e-07 | I68: =10^((-2902.39/F68)+6.498-0.02379*F68) -> 3.3980379e-11 | J68: =D68/(1+(H68/C68)+(H68*I68/C68^2)) -> 0.00024183383 | K68: =J68*H68/C68 -> 6.2303826e-06 | L68: =K68*I68/C68 -> 1.5337089e-11 | M68: =SUM(J68:L68) -> 0.00024806423 | N68: =J68/G68*1000000 -> 4759.2368 | O68: =N68/$Q$2 -> 11.898092 | P68: =J68*1000*12.01 -> 2.9044243
A69: DC1 2020-11-18 | B69: 4.8 | C69: =10^-B69 -> 1.5848932e-05 | D69: =DIC!O68 -> 0.00015664219 | E69: 2 | F69: =E69+273.15 -> 275.15 | G69: =EXP(-58.0931+(90.5069*(100/F69))+(22.294*LN(F69/100))) -> 0.071743773 | H69: =10^((-3404.71/F69)+14.8435-0.032786*F69) -> 2.8081346e-07 | I69: =10^((-2902.39/F69)+6.498-0.02379*F69) -> 2.5339014e-11 | J69: =D69/(1+(H69/C69)+(H69*I69/C69^2)) -> 0.00015391509 | K69: =J69*H69/C69 -> 2.7270879e-06 | L69: =K69*I69/C69 -> 4.3600237e-12 | M69: =SUM(J69:L69) -> 0.00015664219 | N69: =J69/G69*1000000 -> 2145.3443 | O69: =N69/$Q$2 -> 5.3633608 | P69: =J69*1000*12.01 -> 1.8485203
A70: DC1 2022-07-20 | B70: 5.3 | C70: =10^-B70 -> 5.0118723e-06 | D70: =DIC!O69 -> 0.00011871843 | E70: 13.098437 | F70: =E70+273.15 -> 286.24844 | G70: =EXP(-58.0931+(90.5069*(100/F70))+(22.294*LN(F70/100))) -> 0.048391962 | H70: =10^((-3404.71/F70)+14.8435-0.032786*F70) -> 3.6669957e-07 | I70: =10^((-2902.39/F70)+6.498-0.02379*F70) -> 3.5378598e-11 | J70: =D70/(1+(H70/C70)+(H70*I70/C70^2)) -> 0.0001106244 | K70: =J70*H70/C70 -> 8.0939653e-06 | L70: =K70*I70/C70 -> 5.7134963e-11 | M70: =SUM(J70:L70) -> 0.00011871843 | N70: =J70/G70*1000000 -> 2286.0078 | O70: =N70/$Q$2 -> 5.7150195 | P70: =J70*1000*12.01 -> 1.3285991
A71: DC1 2021-03-17 | B71: 5.26 | C71: =10^-B71 -> 5.4954087e-06 | D71: =DIC!O70 -> 0.00026505073 | E71: 2 | F71: =E71+273.15 -> 275.15 | G71: =EXP(-58.0931+(90.5069*(100/F71))+(22.294*LN(F71/100))) -> 0.071743773 | H71: =10^((-3404.71/F71)+14.8435-0.032786*F71) -> 2.8081346e-07 | I71: =10^((-2902.39/F71)+6.498-0.02379*F71) -> 2.5339014e-11 | J71: =D71/(1+(H71/C71)+(H71*I71/C71^2)) -> 0.00025216512 | K71: =J71*H71/C71 -> 1.2885549e-05 | L71: =K71*I71/C71 -> 5.9414529e-11 | M71: =SUM(J71:L71) -> 0.00026505073 | N71: =J71/G71*1000000 -> 3514.8015 | O71: =N71/$Q$2 -> 8.7870038 | P71: =J71*1000*12.01 -> 3.0285031
A72: DC1 2020-12-01 | B72: 4.93 | C72: =10^-B72 -> 1.1748976e-05 | D72: =DIC!O71 -> 0.00016753283 | E72: 2 | F72: =E72+273.15 -> 275.15 | G72: =EXP(-58.0931+(90.5069*(100/F72))+(22.294*LN(F72/100))) -> 0.071743773 | H72: =10^((-3404.71/F72)+14.8435-0.032786*F72) -> 2.8081346e-07 | I72: =10^((-2902.39/F72)+6.498-0.02379*F72) -> 2.5339014e-11 | J72: =D72/(1+(H72/C72)+(H72*I72/C72^2)) -> 0.00016362207 | K72: =J72*H72/C72 -> 3.9107479e-06 | L72: =K72*I72/C72 -> 8.4343095e-12 | M72: =SUM(J72:L72) -> 0.00016753283 | N72: =J72/G72*1000000 -> 2280.645 | O72: =N72/$Q$2 -> 5.7016125 | P72: =J72*1000*12.01 -> 1.9651011
... A187: DC3 2019-10-10 | B187: 5.04 | C187: =10^-B187 -> 9.1201084e-06 | D187: =DIC!O186 -> 7.6300953e-05 | E187: 8.2358333 | F187: =E187+273.15 -> 281.38583 | G187: =EXP(-58.0931+(90.5069*(100/F187))+(22.294*LN(F187/100))) -> 0.057040251 | H187: =10^((-3404.71/F187)+14.8435-0.032786*F187) -> 3.2975566e-07 | I187: =10^((-2902.39/F187)+6.498-0.02379*F187) -> 3.0846346e-11 | J187: =D187/(1+(H187/C187)+(H187*I187/C187^2)) -> 7.3638402e-05 | K187: =J187*H187/C187 -> 2.6625429e-06 | L187: =K187*I187/C187 -> 9.0053446e-12 | M187: =SUM(J187:L187) -> 7.6300953e-05 | N187: =J187/G187*1000000 -> 1290.9901 | O187: =N187/$Q$2 -> 3.2274753 | P187: =J187*1000*12.01 -> 0.8843972
A188: DC3 2025-02-20 | B188: NA | C188: =10^-B188 -> #VALUE! | D188: =DIC!O187 -> 0.0001807877 | E188: 2 | F188: =E188+273.15 -> 275.15 | G188: =EXP(-58.0931+(90.5069*(100/F188))+(22.294*LN(F188/100))) -> 0.071743773 | H188: =10^((-3404.71/F188)+14.8435-0.032786*F188) -> 2.8081346e-07 | I188: =10^((-2902.39/F188)+6.498-0.02379*F188) -> 2.5339014e-11 | J188: =D188/(1+(H188/C188)+(H188*I188/C188^2)) -> #VALUE! | K188: =J188*H188/C188 -> #VALUE! | L188: =K188*I188/C188 -> #VALUE! | M188: =SUM(J188:L188) -> #VALUE! | N188: =J188/G188*1000000 -> #VALUE! | O188: =N188/$Q$2 -> #VALUE! | P188: =J188*1000*12.01 -> #VALUE!
A189: DC3 2022-05-23 | B189: 5.29 | C189: =10^-B189 -> 5.1286138e-06 | D189: =DIC!O188 -> 6.8363629e-05 | E189: 5.6082813 | F189: =E189+273.15 -> 278.75828 | G189: =EXP(-58.0931+(90.5069*(100/F189))+(22.294*LN(F189/100))) -> 0.062663663 | H189: =10^((-3404.71/F189)+14.8435-0.032786*F189) -> 3.0923423e-07 | I189: =10^((-2902.39/F189)+6.498-0.02379*F189) -> 2.8476616e-11 | J189: =D189/(1+(H189/C189)+(H189*I189/C189^2)) -> 6.4475973e-05 | K189: =J189*H189/C189 -> 3.8876349e-06 | L189: =K189*I189/C189 -> 2.1586083e-11 | M189: =SUM(J189:L189) -> 6.8363629e-05 | N189: =J189/G189*1000000 -> 1028.9212 | O189: =N189/$Q$2 -> 2.572303 | P189: =J189*1000*12.01 -> 0.77435643
A190: DC3 2022-06-21 | B190: 4.99 | C190: =10^-B190 -> 1.023293e-05 | D190: =DIC!O189 -> 0.00010647941 | E190: 11.219687 | F190: =E190+273.15 -> 284.36969 | G190: =EXP(-58.0931+(90.5069*(100/F190))+(22.294*LN(F190/100))) -> 0.051491729 | H190: =10^((-3404.71/F190)+14.8435-0.032786*F190) -> 3.526348e-07 | I190: =10^((-2902.39/F190)+6.498-0.02379*F190) -> 3.3608403e-11 | J190: =D190/(1+(H190/C190)+(H190*I190/C190^2)) -> 0.00010293227 | K190: =J190*H190/C190 -> 3.5471269e-06 | L190: =K190*I190/C190 -> 1.1649964e-11 | M190: =SUM(J190:L190) -> 0.00010647941 | N190: =J190/G190*1000000 -> 1999.006 | O190: =N190/$Q$2 -> 4.9975149 | P190: =J190*1000*12.01 -> 1.2362166
A191: DC3 2021-09-01 | B191: 4.76 | C191: =10^-B191 -> 1.7378008e-05 | D191: =DIC!O190 -> 0.00016258179 | E191: 9.5078125 | F191: =E191+273.15 -> 282.65781 | G191: =EXP(-58.0931+(90.5069*(100/F191))+(22.294*LN(F191/100))) -> 0.054574394 | H191: =10^((-3404.71/F191)+14.8435-0.032786*F191) -> 3.395776e-07 | I191: =10^((-2902.39/F191)+6.498-0.02379*F191) -> 3.2015468e-11 | J191: =D191/(1+(H191/C191)+(H191*I191/C191^2)) -> 0.00015946572 | K191: =J191*H191/C191 -> 3.1160641e-06 | L191: =K191*I191/C191 -> 5.7407183e-12 | M191: =SUM(J191:L191) -> 0.00016258179 | N191: =J191/G191*1000000 -> 2921.988 | O191: =N191/$Q$2 -> 7.30497 | P191: =J191*1000*12.01 -> 1.9151834
A192: DC3 2021-05-14 | B192: 4.97 | C192: =10^-B192 -> 1.0715193e-05 | D192: =DIC!O191 -> 0.00010052724 | E192: 7.6369479 | F192: =E192+273.15 -> 280.78695 | G192: =EXP(-58.0931+(90.5069*(100/F192))+(22.294*LN(F192/100))) -> 0.058256802 | H192: =10^((-3404.71/F192)+14.8435-0.032786*F192) -> 3.2510219e-07 | I192: =10^((-2902.39/F192)+6.498-0.02379*F192) -> 3.0300606e-11 | J192: =D192/(1+(H192/C192)+(H192*I192/C192^2)) -> 9.7567021e-05 | K192: =J192*H192/C192 -> 2.9602128e-06 | L192: =K192*I192/C192 -> 8.3709406e-12 | M192: =SUM(J192:L192) -> 0.00010052724 | N192: =J192/G192*1000000 -> 1674.7748 | O192: =N192/$Q$2 -> 4.1869369 | P192: =J192*1000*12.01 -> 1.1717799
A193: DC3 2022-05-06 | B193: 5.28 | C193: =10^-B193 -> 5.2480746e-06 | D193: =DIC!O192 -> 9.8436632e-05 | E193: 2 | F193: =E193+273.15 -> 275.15 | G193: =EXP(-58.0931+(90.5069*(100/F193))+(22.294*LN(F193/100))) -> 0.071743773 | H193: =10^((-3404.71/F193)+14.8435-0.032786*F193) -> 2.8081346e-07 | I193: =10^((-2902.39/F193)+6.498-0.02379*F193) -> 2.5339014e-11 | J193: =D193/(1+(H193/C193)+(H193*I193/C193^2)) -> 9.3436991e-05 | K193: =J193*H193/C193 -> 4.9996174e-06 | L193: =K193*I193/C193 -> 2.4139401e-11 | M193: =SUM(J193:L193) -> 9.8436632e-05 | N193: =J193/G193*1000000 -> 1302.3707 | O193: =N193/$Q$2 -> 3.2559269 | P193: =J193*1000*12.01 -> 1.1221783
A194: DC3 2020-12-01 | B194: 4.89 | C194: =10^-B194 -> 1.2882496e-05 | D194: =DIC!O193 -> 0.00015216483 | E194: 2 | F194: =E194+273.15 -> 275.15 | G194: =EXP(-58.0931+(90.5069*(100/F194))+(22.294*LN(F194/100))) -> 0.071743773 | H194: =10^((-3404.71/F194)+14.8435-0.032786*F194) -> 2.8081346e-07 | I194: =10^((-2902.39/F194)+6.498-0.02379*F194) -> 2.5339014e-11 | J194: =D194/(1+(H194/C194)+(H194*I194/C194^2)) -> 0.00014891869 | K194: =J194*H194/C194 -> 3.2461391e-06 | L194: =K194*I194/C194 -> 6.3849402e-12 | M194: =SUM(J194:L194) -> 0.00015216483 | N194: =J194/G194*1000000 -> 2075.7019 | O194: =N194/$Q$2 -> 5.1892548 | P194: =J194*1000*12.01 -> 1.7885134
A195: DC3 2024-03-13 | B195: 5.82 | C195: =10^-B195 -> 1.5135612e-06 | D195: =DIC!O194 -> 0.00039287231 | E195: 2 | F195: =E195+273.15 -> 275.15 | G195: =EXP(-58.0931+(90.5069*(100/F195))+(22.294*LN(F195/100))) -> 0.071743773 | H195: =10^((-3404.71/F195)+14.8435-0.032786*F195) -> 2.8081346e-07 | I195: =10^((-2902.39/F195)+6.498-0.02379*F195) -> 2.5339014e-11 | J195: =D195/(1+(H195/C195)+(H195*I195/C195^2)) -> 0.00033138828 | K195: =J195*H195/C195 -> 6.1483003e-05 | L195: =K195*I195/C195 -> 1.0293067e-09 | M195: =SUM(J195:L195) -> 0.00039287231 | N195: =J195/G195*1000000 -> 4619.0529 | O195: =N195/$Q$2 -> 11.547632 | P195: =J195*1000*12.01 -> 3.9799733
...

Sheet CH4
C1: Raw GC data
B3: K | C3: ppm | D3: mol | E3: mol | F3: umol L-1 | G3: mol L-1 atm-1 | H3: uatm | I3: - | J3: ug L-1
A4: Bottle Nr | B4: T | C4: CH4 | D4: CH4 dis | E4: CH4 gas | F4: CH4 | G4: KH | H4: pCH4 | I4: EpCH4 | J4: CH4-C
A6: DC4 2019-12-12 | B6: ='C-speciation'!F8 -> 275.15 | C6: 18.662269 | D6: =(((C6/1000000)*((0.0013))*Volumes!B3/1000)*((Volumes!B3+Volumes!C3)/Volumes!C3)) -> 1.608501e-10 | E6: =(((Volumes!B3+Volumes!C3)/Volumes!C3)*(Volumes!C3/1000*(C6/1000000)))/(0.082057*308.15) -> 1.6310937e-08 | F6: =(D6+E6)*(1000/Volumes!D3)*1000000 -> 3.2943574 | G6: =EXP(-68.8862+(101.4956*(100/B6))+(28.7314*LN(B6/100)))/22.4 -> 0.0024114849 | H6: =F6/G6 -> 1366.1116 | I6: =H6/1.9 -> 719.0061 | J6: =F6*12.01 -> 39.565232
A7: DC4 2019-11-20 | B7: ='C-speciation'!F9 -> 275.15 | C7: 7.3802037 | D7: =(((C7/1000000)*((0.0013))*Volumes!B4/1000)*((Volumes!B4+Volumes!C4)/Volumes!C4)) -> 6.3609976e-11 | E7: =(((Volumes!B4+Volumes!C4)/Volumes!C4)*(Volumes!C4/1000*(C7/1000000)))/(0.082057*308.15) -> 6.4503431e-09 | F7: =(D7+E7)*(1000/Volumes!D4)*1000000 -> 1.3027906 | G7: =EXP(-68.8862+(101.4956*(100/B7))+(28.7314*LN(B7/100)))/22.4 -> 0.0024114849 | H7: =F7/G7 -> 540.24416 | I7: =H7/1.9 -> 284.33903 | J7: =F7*12.01 -> 15.646515
A8: DC4 2022-05-16 | B8: ='C-speciation'!F10 -> 281.68623 | C8: 4.03 | D8: =(((C8/1000000)*((0.0013))*Volumes!B5/1000)*((Volumes!B5+Volumes!C5)/Volumes!C5)) -> 3.473457e-11 | E8: =(((Volumes!B5+Volumes!C5)/Volumes!C5)*(Volumes!C5/1000*(C8/1000000)))/(0.082057*308.15) -> 3.5222446e-09 | F8: =(D8+E8)*(1000/Volumes!D5)*1000000 -> 0.71139584 | G8: =EXP(-68.8862+(101.4956*(100/B8))+(28.7314*LN(B8/100)))/22.4 -> 0.0020114355 | H8: =F8/G8 -> 353.67569 | I8: =H8/1.9 -> 186.1451 | J8: =F8*12.01 -> 8.543864
A9: DC4 2021-05-25 | B9: ='C-speciation'!F11 -> 281.59945 | C9: NA | D9: =(((C9/1000000)*((0.0013))*Volumes!B6/1000)*((Volumes!B6+Volumes!C6)/Volumes!C6)) -> #VALUE! | E9: =(((Volumes!B6+Volumes!C6)/Volumes!C6)*(Volumes!C6/1000*(C9/1000000)))/(0.082057*308.15) -> #VALUE! | F9: =(D9+E9)*(1000/Volumes!D6)*1000000 -> #VALUE! | G9: =EXP(-68.8862+(101.4956*(100/B9))+(28.7314*LN(B9/100)))/22.4 -> 0.0020159684 | H9: =F9/G9 -> #VALUE! | I9: =H9/1.9 -> #VALUE! | J9: =F9*12.01 -> #VALUE!
A10: DC4 2022-02-09 | B10: ='C-speciation'!F12 -> 275.15 | C10: 195.37 | D10: =(((C10/1000000)*((0.0013))*Volumes!B7/1000)*((Volumes!B7+Volumes!C7)/Volumes!C7)) -> 1.683894e-09 | E10: =(((Volumes!B7+Volumes!C7)/Volumes!C7)*(Volumes!C7/1000*(C10/1000000)))/(0.082057*308.15) -> 1.7075457e-07 | F10: =(D10+E10)*(1000/Volumes!D7)*1000000 -> 34.487693 | G10: =EXP(-68.8862+(101.4956*(100/B10))+(28.7314*LN(B10/100)))/22.4 -> 0.0024114849 | H10: =F10/G10 -> 14301.435 | I10: =H10/1.9 -> 7527.0709 | J10: =F10*12.01 -> 414.1972
A11: DC4 2020-11-03 | B11: ='C-speciation'!F13 -> 275.15 | C11: 0.85512239 | D11: =(((C11/1000000)*((0.0013))*Volumes!B8/1000)*((Volumes!B8+Volumes!C8)/Volumes!C8)) -> 7.3702999e-12 | E11: =(((Volumes!B8+Volumes!C8)/Volumes!C8)*(Volumes!C8/1000*(C11/1000000)))/(0.082057*308.15) -> 7.4738219e-10 | F11: =(D11+E11)*(1000/Volumes!D8)*1000000 -> 0.1509505 | G11: =EXP(-68.8862+(101.4956*(100/B11))+(28.7314*LN(B11/100)))/22.4 -> 0.0024114849 | H11: =F11/G11 -> 62.596494 | I11: =H11/1.9 -> 32.945523 | J11: =F11*12.01 -> 1.8129155
A12: DC4 2021-07-07 | B12: ='C-speciation'!F14 -> 290.57292 | C12: 540.77432 | D12: =(((C12/1000000)*((0.0013))*Volumes!B9/1000)*((Volumes!B9+Volumes!C9)/Volumes!C9)) -> 4.6609339e-09 | E12: =(((Volumes!B9+Volumes!C9)/Volumes!C9)*(Volumes!C9/1000*(C12/1000000)))/(0.082057*308.15) -> 4.7264006e-07 | F12: =(D12+E12)*(1000/Volumes!D9)*1000000 -> 95.460198 | G12: =EXP(-68.8862+(101.4956*(100/B12))+(28.7314*LN(B12/100)))/22.4 -> 0.0016311844 | H12: =F12/G12 -> 58522.014 | I12: =H12/1.9 -> 30801.06 | J12: =F12*12.01 -> 1146.477
A13: DC4 2021-04-29 | B13: ='C-speciation'!F15 -> 275.15 | C13: NA | D13: =(((C13/1000000)*((0.0013))*Volumes!B10/1000)*((Volumes!B10+Volumes!C10)/Volumes!C10)) -> #VALUE! | E13: =(((Volumes!B10+Volumes!C10)/Volumes!C10)*(Volumes!C10/1000*(C13/1000000)))/(0.082057*308.15) -> #VALUE! | F13: =(D13+E13)*(1000/Volumes!D10)*1000000 -> #VALUE! | G13: =EXP(-68.8862+(101.4956*(100/B13))+(28.7314*LN(B13/100)))/22.4 -> 0.0024114849 | H13: =F13/G13 -> #VALUE! | I13: =H13/1.9 -> #VALUE! | J13: =F13*12.01 -> #VALUE!
A14: DC4 2021-08-03 | B14: ='C-speciation'!F16 -> 285.51458 | C14: 32.188845 | D14: =(((C14/1000000)*((0.0013))*Volumes!B11/1000)*((Volumes!B11+Volumes!C11)/Volumes!C11)) -> 2.7743565e-10 | E14: =(((Volumes!B11+Volumes!C11)/Volumes!C11)*(Volumes!C11/1000*(C14/1000000)))/(0.082057*308.15) -> 2.8133247e-08 | F14: =(D14+E14)*(1000/Volumes!D11)*1000000 -> 5.6821365 | G14: =EXP(-68.8862+(101.4956*(100/B14))+(28.7314*LN(B14/100)))/22.4 -> 0.001828638 | H14: =F14/G14 -> 3107.3053 | I14: =H14/1.9 -> 1635.4238 | J14: =F14*12.01 -> 68.24246
A15: DC4 2022-05-06 | B15: ='C-speciation'!F17 -> 275.15 | C15: 1.62 | D15: =(((C15/1000000)*((0.0013))*Volumes!B12/1000)*((Volumes!B12+Volumes!C12)/Volumes!C12)) -> 1.396278e-11 | E15: =(((Volumes!B12+Volumes!C12)/Volumes!C12)*(Volumes!C12/1000*(C15/1000000)))/(0.082057*308.15) -> 1.4158899e-09 | F15: =(D15+E15)*(1000/Volumes!D12)*1000000 -> 0.28597053 | G15: =EXP(-68.8862+(101.4956*(100/B15))+(28.7314*LN(B15/100)))/22.4 -> 0.0024114849 | H15: =F15/G15 -> 118.58691 | I15: =H15/1.9 -> 62.414162 | J15: =F15*12.01 -> 3.4345061
A16: DC4 2021-04-08 | B16: ='C-speciation'!F18 -> 275.15 | C16: NA | D16: =(((C16/1000000)*((0.0013))*Volumes!B13/1000)*((Volumes!B13+Volumes!C13)/Volumes!C13)) -> #VALUE! | E16: =(((Volumes!B13+Volumes!C13)/Volumes!C13)*(Volumes!C13/1000*(C16/1000000)))/(0.082057*308.15) -> #VALUE! | F16: =(D16+E16)*(1000/Volumes!D13)*1000000 -> #VALUE! | G16: =EXP(-68.8862+(101.4956*(100/B16))+(28.7314*LN(B16/100)))/22.4 -> 0.0024114849 | H16: =F16/G16 -> #VALUE! | I16: =H16/1.9 -> #VALUE! | J16: =F16*12.01 -> #VALUE!
A17: DC4 2021-06-21 | B17: ='C-speciation'!F19 -> 284.36969 | C17: 1.8950095 | D17: =(((C17/1000000)*((0.0013))*Volumes!B14/1000)*((Volumes!B14+Volumes!C14)/Volumes!C14)) -> 1.6333087e-11 | E17: =(((Volumes!B14+Volumes!C14)/Volumes!C14)*(Volumes!C14/1000*(C17/1000000)))/(0.082057*308.15) -> 1.6562499e-09 | F17: =(D17+E17)*(1000/Volumes!D14)*1000000 -> 0.3345166 | G17: =EXP(-68.8862+(101.4956*(100/B17))+(28.7314*LN(B17/100)))/22.4 -> 0.0018799573 | H17: =F17/G17 -> 177.9384 | I17: =H17/1.9 -> 93.651788 | J17: =F17*12.01 -> 4.0175443
A18: DC4 2021-11-24 | B18: ='C-speciation'!F20 -> 275.15 | C18: 16.03512 | D18: =(((C18/1000000)*((0.0013))*Volumes!B15/1000)*((Volumes!B15+Volumes!C15)/Volumes!C15)) -> 1.382067e-10 | E18: =(((Volumes!B15+Volumes!C15)/Volumes!C15)*(Volumes!C15/1000*(C18/1000000)))/(0.082057*308.15) -> 1.4014792e-08 | F18: =(D18+E18)*(1000/Volumes!D15)*1000000 -> 2.8305998 | G18: =EXP(-68.8862+(101.4956*(100/B18))+(28.7314*LN(B18/100)))/22.4 -> 0.0024114849 | H18: =F18/G18 -> 1173.7995 | I18: =H18/1.9 -> 617.78924 | J18: =F18*12.01 -> 33.995504
A19: DC4 2021-07-19 | B19: ='C-speciation'!F21 -> 286.38031 | C19: 9.7915788 | D19: =(((C19/1000000)*((0.0013))*Volumes!B16/1000)*((Volumes!B16+Volumes!C16)/Volumes!C16)) -> 8.4393617e-11 | E19: =(((Volumes!B16+Volumes!C16)/Volumes!C16)*(Volumes!C16/1000*(C19/1000000)))/(0.082057*308.15) -> 8.5578996e-09 | F19: =(D19+E19)*(1000/Volumes!D16)*1000000 -> 1.7284586 | G19: =EXP(-68.8862+(101.4956*(100/B19))+(28.7314*LN(B19/100)))/22.4 -> 0.0017915755 | H19: =F19/G19 -> 964.77018 | I19: =H19/1.9 -> 507.77378 | J19: =F19*12.01 -> 20.758788
A20: DC4 2021-10-12 | B20: ='C-speciation'!F22 -> 279.36392 | C20: 5.3118538 | D20: =(((C20/1000000)*((0.0013))*Volumes!B17/1000)*((Volumes!B17+Volumes!C17)/Volumes!C17)) -> 4.5782868e-11 | E20: =(((Volumes!B17+Volumes!C17)/Volumes!C17)*(Volumes!C17/1000*(C20/1000000)))/(0.082057*308.15) -> 4.6425927e-09 | F20: =(D20+E20)*(1000/Volumes!D17)*1000000 -> 0.93767511 | G20: =EXP(-68.8862+(101.4956*(100/B20))+(28.7314*LN(B20/100)))/22.4 -> 0.0021393886 | H20: =F20/G20 -> 438.29116 | I20: =H20/1.9 -> 230.67956 | J20: =F20*12.01 -> 11.261478
A21: DC4 2020-08-10 | B21: ='C-speciation'!F23 -> 287.24396 | C21: 518.02986 | D21: =(((C21/1000000)*((0.0013))*Volumes!B18/1000)*((Volumes!B18+Volumes!C18)/Volumes!C18)) -> 4.4648993e-09 | E21: =(((Volumes!B18+Volumes!C18)/Volumes!C18)*(Volumes!C18/1000*(C21/1000000)))/(0.082057*308.15) -> 4.5276126e-07 | F21: =(D21+E21)*(1000/Volumes!D18)*1000000 -> 91.445231 | G21: =EXP(-68.8862+(101.4956*(100/B21))+(28.7314*LN(B21/100)))/22.4 -> 0.0017560246 | H21: =F21/G21 -> 52075.142 | I21: =H21/1.9 -> 27407.97 | J21: =F21*12.01 -> 1098.2572
A22: DC4 2021-04-20 | B22: ='C-speciation'!F24 -> 275.15 | C22: NA | D22: =(((C22/1000000)*((0.0013))*Volumes!B19/1000)*((Volumes!B19+Volumes!C19)/Volumes!C19)) -> #VALUE! | E22: =(((Volumes!B19+Volumes!C19)/Volumes!C19)*(Volumes!C19/1000*(C22/1000000)))/(0.082057*308.15) -> #VALUE! | F22: =(D22+E22)*(1000/Volumes!D19)*1000000 -> #VALUE! | G22: =EXP(-68.8862+(101.4956*(100/B22))+(28.7314*LN(B22/100)))/22.4 -> 0.0024114849 | H22: =F22/G22 -> #VALUE! | I22: =H22/1.9 -> #VALUE! | J22: =F22*12.01 -> #VALUE!
A23: DC4 2020-04-24 | B23: ='C-speciation'!F25 -> 275.15 | C23: 1.0166359 | D23: =(((C23/1000000)*((0.0013))*Volumes!B20/1000)*((Volumes!B20+Volumes!C20)/Volumes!C20)) -> 8.7623847e-12 | E23: =(((Volumes!B20+Volumes!C20)/Volumes!C20)*(Volumes!C20/1000*(C23/1000000)))/(0.082057*308.15) -> 8.8854597e-10 | F23: =(D23+E23)*(1000/Volumes!D20)*1000000 -> 0.17946167 | G23: =EXP(-68.8862+(101.4956*(100/B23))+(28.7314*LN(B23/100)))/22.4 -> 0.0024114849 | H23: =F23/G23 -> 74.419572 | I23: =H23/1.9 -> 39.168196 | J23: =F23*12.01 -> 2.1553347
A24: DC4 2020-11-18 | B24: ='C-speciation'!F26 -> 275.15 | C24: 0.85660535 | D24: =(((C24/1000000)*((0.0013))*Volumes!B21/1000)*((Volumes!B21+Volumes!C21)/Volumes!C21)) -> 7.3830815e-12 | E24: =(((Volumes!B21+Volumes!C21)/Volumes!C21)*(Volumes!C21/1000*(C24/1000000)))/(0.082057*308.15) -> 7.486783e-10 | F24: =(D24+E24)*(1000/Volumes!D21)*1000000 -> 0.15121228 | G24: =EXP(-68.8862+(101.4956*(100/B24))+(28.7314*LN(B24/100)))/22.4 -> 0.0024114849 | H24: =F24/G24 -> 62.70505 | I24: =H24/1.9 -> 33.002658 | J24: =F24*12.01 -> 1.8160594
A25: DC4 2021-09-01 | B25: ='C-speciation'!F27 -> 282.65781 | C25: 52.319831 | D25: =(((C25/1000000)*((0.0013))*Volumes!B22/1000)*((Volumes!B22+Volumes!C22)/Volumes!C22)) -> 4.5094462e-10 | E25: =(((Volumes!B22+Volumes!C22)/Volumes!C22)*(Volumes!C22/1000*(C25/1000000)))/(0.082057*308.15) -> 4.5727851e-08 | F25: =(D25+E25)*(1000/Volumes!D22)*1000000 -> 9.2357592 | G25: =EXP(-68.8862+(101.4956*(100/B25))+(28.7314*LN(B25/100)))/22.4 -> 0.0019619253 | H25: =F25/G25 -> 4707.498 | I25: =H25/1.9 -> 2477.6305 | J25: =F25*12.01 -> 110.92147
A26: DC4 2023-09-14 | B26: ='C-speciation'!F28 -> 280.53905 | C26: 55.94 | D26: =(((C26/1000000)*((0.0013))*Volumes!B23/1000)*((Volumes!B23+Volumes!C23)/Volumes!C23)) -> 4.8214686e-10 | E26: =(((Volumes!B23+Volumes!C23)/Volumes!C23)*(Volumes!C23/1000*(C26/1000000)))/(0.082057*308.15) -> 4.8891902e-08 | F26: =(D26+E26)*(1000/Volumes!D23)*1000000 -> 9.8748097 | G26: =EXP(-68.8862+(101.4956*(100/B26))+(28.7314*LN(B26/100)))/22.4 -> 0.002072881 | H26: =F26/G26 -> 4763.8091 | I26: =H26/1.9 -> 2507.268 | J26: =F26*12.01 -> 118.59646
A27: DC4 2022-06-21 | B27: ='C-speciation'!F29 -> 284.36969 | C27: 7.39 | D27: =(((C27/1000000)*((0.0013))*Volumes!B24/1000)*((Volumes!B24+Volumes!C24)/Volumes!C24)) -> 6.369441e-11 | E27: =(((Volumes!B24+Volumes!C24)/Volumes!C24)*(Volumes!C24/1000*(C27/1000000)))/(0.082057*308.15) -> 6.4589051e-09 | F27: =(D27+E27)*(1000/Volumes!D24)*1000000 -> 1.3045199 | G27: =EXP(-68.8862+(101.4956*(100/B27))+(28.7314*LN(B27/100)))/22.4 -> 0.0018799573 | H27: =F27/G27 -> 693.90931 | I27: =H27/1.9 -> 365.21543 | J27: =F27*12.01 -> 15.667284
A28: DC4 2022-05-23 | B28: ='C-speciation'!F30 -> 278.75828 | C28: 15.18 | D28: =(((C28/1000000)*((0.0013))*Volumes!B25/1000)*((Volumes!B25+Volumes!C25)/Volumes!C25)) -> 1.3083642e-10 | E28: =(((Volumes!B25+Volumes!C25)/Volumes!C25)*(Volumes!C25/1000*(C28/1000000)))/(0.082057*308.15) -> 1.3267413e-08 | F28: =(D28+E28)*(1000/Volumes!D25)*1000000 -> 2.6796498 | G28: =EXP(-68.8862+(101.4956*(100/B28))+(28.7314*LN(B28/100)))/22.4 -> 0.0021751524 | H28: =F28/G28 -> 1231.9366 | I28: =H28/1.9 -> 648.38766 | J28: =F28*12.01 -> 32.182594
A29: DC4 2023-08-30 | B29: ='C-speciation'!F31 -> 283.9101 | C29: 4.39 | D29: =(((C29/1000000)*((0.0013))*Volumes!B26/1000)*((Volumes!B26+Volumes!C26)/Volumes!C26)) -> 3.783741e-11 | E29: =(((Volumes!B26+Volumes!C26)/Volumes!C26)*(Volumes!C26/1000*(C29/1000000)))/(0.082057*308.15) -> 3.8368868e-09 | F29: =(D29+E29)*(1000/Volumes!D26)*1000000 -> 0.77494484 | G29: =EXP(-68.8862+(101.4956*(100/B29))+(28.7314*LN(B29/100)))/22.4 -> 0.0019013294 | H29: =F29/G29 -> 407.58053 | I29: =H29/1.9 -> 214.51607 | J29: =F29*12.01 -> 9.3070876
A30: DC4 2024-09-10 | B30: ='C-speciation'!F32 -> 281.38429 | C30: 22.35 | D30: =(((C30/1000000)*((0.0013))*Volumes!B27/1000)*((Volumes!B27+Volumes!C27)/Volumes!C27)) -> 1.9263465e-10 | E30: =(((Volumes!B27+Volumes!C27)/Volumes!C27)*(Volumes!C27/1000*(C30/1000000)))/(0.082057*308.15) -> 1.9534036e-08 | F30: =(D30+E30)*(1000/Volumes!D27)*1000000 -> 3.9453342 | G30: =EXP(-68.8862+(101.4956*(100/B30))+(28.7314*LN(B30/100)))/22.4 -> 0.002027287 | H30: =F30/G30 -> 1946.1153 | I30: =H30/1.9 -> 1024.2712 | J30: =F30*12.01 -> 47.383464
A31: DC4 2024-07-16 | B31: ='C-speciation'!F33 -> 288.03625 | C31: 41.96 | D31: =(((C31/1000000)*((0.0013))*Volumes!B28/1000)*((Volumes!B28+Volumes!C28)/Volumes!C28)) -> 3.6165324e-10 | E31: =(((Volumes!B28+Volumes!C28)/Volumes!C28)*(Volumes!C28/1000*(C31/1000000)))/(0.082057*308.15) -> 3.6673296e-08 | F31: =(D31+E31)*(1000/Volumes!D28)*1000000 -> 7.4069899 | G31: =EXP(-68.8862+(101.4956*(100/B31))+(28.7314*LN(B31/100)))/22.4 -> 0.0017246068 | H31: =F31/G31 -> 4294.8862 | I31: =H31/1.9 -> 2260.4664 | J31: =F31*12.01 -> 88.957949
A32: DC4 2021-05-14 | B32: ='C-speciation'!F34 -> 280.78695 | C32: 1.0561389 | D32: =(((C32/1000000)*((0.0013))*Volumes!B29/1000)*((Volumes!B29+Volumes!C29)/Volumes!C29)) -> 9.102861e-12 | E32: =(((Volumes!B29+Volumes!C29)/Volumes!C29)*(Volumes!C29/1000*(C32/1000000)))/(0.082057*308.15) -> 9.2307183e-10 | F32: =(D32+E32)*(1000/Volumes!D29)*1000000 -> 0.18643494 | G32: =EXP(-68.8862+(101.4956*(100/B32))+(28.7314*LN(B32/100)))/22.4 -> 0.0020593196 | H32: =F32/G32 -> 90.532298 | I32: =H32/1.9 -> 47.648578 | J32: =F32*12.01 -> 2.2390836
A33: DC4 2021-05-04 | B33: ='C-speciation'!F35 -> 275.15 | C33: 1.120683 | D33: =(((C33/1000000)*((0.0013))*Volumes!B30/1000)*((Volumes!B30+Volumes!C30)/Volumes!C30)) -> 9.6591664e-12 | E33: =(((Volumes!B30+Volumes!C30)/Volumes!C30)*(Volumes!C30/1000*(C33/1000000)))/(0.082057*308.15) -> 9.7948374e-10 | F33: =(D33+E33)*(1000/Volumes!D30)*1000000 -> 0.19782858 | G33: =EXP(-68.8862+(101.4956*(100/B33))+(28.7314*LN(B33/100)))/22.4 -> 0.0024114849 | H33: =F33/G33 -> 82.036004 | I33: =H33/1.9 -> 43.176844 | J33: =F33*12.01 -> 2.3759213
A34: DC4 2020-08-24 | B34: ='C-speciation'!F36 -> 282.86077 | C34: 620.18578 | D34: =(((C34/1000000)*((0.0013))*Volumes!B31/1000)*((Volumes!B31+Volumes!C31)/Volumes!C31)) -> 5.3453812e-09 | E34: =(((Volumes!B31+Volumes!C31)/Volumes!C31)*(Volumes!C31/1000*(C34/1000000)))/(0.082057*308.15) -> 5.4204616e-07 | F34: =(D34+E34)*(1000/Volumes!D31)*1000000 -> 109.47831 | G34: =EXP(-68.8862+(101.4956*(100/B34))+(28.7314*LN(B34/100)))/22.4 -> 0.0019518636 | H34: =F34/G34 -> 56089.119 | I34: =H34/1.9 -> 29520.589 | J34: =F34*12.01 -> 1314.8345
... A42: DC4 2021-05-10 | B42: ='C-speciation'!F44 -> 275.94215 | C42: 0.87230448 | D42: =(((C42/1000000)*((0.0013))*Volumes!B39/1000)*((Volumes!B39+Volumes!C39)/Volumes!C39)) -> 7.5183923e-12 | E42: =(((Volumes!B39+Volumes!C39)/Volumes!C39)*(Volumes!C39/1000*(C42/1000000)))/(0.082057*308.15) -> 7.6239944e-10 | F42: =(D42+E42)*(1000/Volumes!D39)*1000000 -> 0.15398357 | G42: =EXP(-68.8862+(101.4956*(100/B42))+(28.7314*LN(B42/100)))/22.4 -> 0.0023559593 | H42: =F42/G42 -> 65.35918 | I42: =H42/1.9 -> 34.399568 | J42: =F42*12.01 -> 1.8493426
A43: DC4 2021-04-21 | B43: ='C-speciation'!F45 -> 275.15 | C43: NA | D43: =(((C43/1000000)*((0.0013))*Volumes!B40/1000)*((Volumes!B40+Volumes!C40)/Volumes!C40)) -> #VALUE! | E43: =(((Volumes!B40+Volumes!C40)/Volumes!C40)*(Volumes!C40/1000*(C43/1000000)))/(0.082057*308.15) -> #VALUE! | F43: =(D43+E43)*(1000/Volumes!D40)*1000000 -> #VALUE! | G43: =EXP(-68.8862+(101.4956*(100/B43))+(28.7314*LN(B43/100)))/22.4 -> 0.0024114849 | H43: =F43/G43 -> #VALUE! | I43: =H43/1.9 -> #VALUE! | J43: =F43*12.01 -> #VALUE!
A44: DC4 2019-10-10 | B44: ='C-speciation'!F46 -> 281.38583 | C44: 4.6710595 | D44: =(((C44/1000000)*((0.0013))*Volumes!B41/1000)*((Volumes!B41+Volumes!C41)/Volumes!C41)) -> 4.0259862e-11 | E44: =(((Volumes!B41+Volumes!C41)/Volumes!C41)*(Volumes!C41/1000*(C44/1000000)))/(0.082057*308.15) -> 4.0825345e-09 | F44: =(D44+E44)*(1000/Volumes!D41)*1000000 -> 0.82455888 | G44: =EXP(-68.8862+(101.4956*(100/B44))+(28.7314*LN(B44/100)))/22.4 -> 0.0020272055 | H44: =F44/G44 -> 406.74657 | I44: =H44/1.9 -> 214.07714 | J44: =F44*12.01 -> 9.9029521
A45: DC4 2023-05-03 | B45: ='C-speciation'!F47 -> 275.15 | C45: 0.71 | D45: =(((C45/1000000)*((0.0013))*Volumes!B42/1000)*((Volumes!B42+Volumes!C42)/Volumes!C42)) -> 6.11949e-12 | E45: =(((Volumes!B42+Volumes!C42)/Volumes!C42)*(Volumes!C42/1000*(C45/1000000)))/(0.082057*308.15) -> 6.2054433e-10 | F45: =(D45+E45)*(1000/Volumes!D42)*1000000 -> 0.12533276 | G45: =EXP(-68.8862+(101.4956*(100/B45))+(28.7314*LN(B45/100)))/22.4 -> 0.0024114849 | H45: =F45/G45 -> 51.973275 | I45: =H45/1.9 -> 27.354355 | J45: =F45*12.01 -> 1.5052465
A46: DC4 2021-08-18 | B46: ='C-speciation'!F48 -> 286.00937 | C46: 5.8634426 | D46: =(((C46/1000000)*((0.0013))*Volumes!B43/1000)*((Volumes!B43+Volumes!C43)/Volumes!C43)) -> 5.0537011e-11 | E46: =(((Volumes!B43+Volumes!C43)/Volumes!C43)*(Volumes!C43/1000*(C46/1000000)))/(0.082057*308.15) -> 5.1246846e-09 | F46: =(D46+E46)*(1000/Volumes!D43)*1000000 -> 1.0350443 | G46: =EXP(-68.8862+(101.4956*(100/B46))+(28.7314*LN(B46/100)))/22.4 -> 0.0018072771 | H46: =F46/G46 -> 572.70927 | I46: =H46/1.9 -> 301.42593 | J46: =F46*12.01 -> 12.430882
A47: DC4 2019-04-21 | B47: ='C-speciation'!F49 -> 275.15 | C47: 1.2452587 | D47: =(((C47/1000000)*((0.0013))*Volumes!B44/1000)*((Volumes!B44+Volumes!C44)/Volumes!C44)) -> 1.0732885e-11 | E47: =(((Volumes!B44+Volumes!C44)/Volumes!C44)*(Volumes!C44/1000*(C47/1000000)))/(0.082057*308.15) -> 1.0883637e-09 | F47: =(D47+E47)*(1000/Volumes!D44)*1000000 -> 0.21981932 | G47: =EXP(-68.8862+(101.4956*(100/B47))+(28.7314*LN(B47/100)))/22.4 -> 0.0024114849 | H47: =F47/G47 -> 91.155175 | I47: =H47/1.9 -> 47.976408 | J47: =F47*12.01 -> 2.6400301
A48: DC4 2021-03-17 | B48: ='C-speciation'!F50 -> 275.15 | C48: NA | D48: =(((C48/1000000)*((0.0013))*Volumes!B45/1000)*((Volumes!B45+Volumes!C45)/Volumes!C45)) -> #VALUE! | E48: =(((Volumes!B45+Volumes!C45)/Volumes!C45)*(Volumes!C45/1000*(C48/1000000)))/(0.082057*308.15) -> #VALUE! | F48: =(D48+E48)*(1000/Volumes!D45)*1000000 -> #VALUE! | G48: =EXP(-68.8862+(101.4956*(100/B48))+(28.7314*LN(B48/100)))/22.4 -> 0.0024114849 | H48: =F48/G48 -> #VALUE! | I48: =H48/1.9 -> #VALUE! | J48: =F48*12.01 -> #VALUE!
A49: DC4 2021-02-17 | B49: ='C-speciation'!F51 -> 275.15 | C49: NA | D49: =(((C49/1000000)*((0.0013))*Volumes!B46/1000)*((Volumes!B46+Volumes!C46)/Volumes!C46)) -> #VALUE! | E49: =(((Volumes!B46+Volumes!C46)/Volumes!C46)*(Volumes!C46/1000*(C49/1000000)))/(0.082057*308.15) -> #VALUE! | F49: =(D49+E49)*(1000/Volumes!D46)*1000000 -> #VALUE! | G49: =EXP(-68.8862+(101.4956*(100/B49))+(28.7314*LN(B49/100)))/22.4 -> 0.0024114849 | H49: =F49/G49 -> #VALUE! | I49: =H49/1.9 -> #VALUE! | J49: =F49*12.01 -> #VALUE!
...

Sheet Data summary
A1: Sample ID | B1: SiteId_DC | C1: Date | D1: DIC_mgL | E1: CO2_mgL | F1: pCO2_uatm | G1: pCH4_uatm | H1: CH4_ugL
A2: DC4 2019-12-12 | B2: DC4 | C2: 43811 | D2: 6.1513368 | E2: 6.1286538 | F2: 7112.7554 | G2: 1366.1116 | H2: 39.565232
A3: DC4 2019-11-20 | B3: DC4 | C3: 43789 | D3: 4.2951094 | E3: 4.2806289 | F3: 4967.9859 | G3: 540.24416 | H3: 15.646515
A4: DC4 2022-05-16 | B4: DC4 | C4: 44697 | D4: 3.3684638 | E4: 3.3470044 | F4: 4937.3948 | G4: 353.67569 | H4: 8.543864
A5: DC4 2021-05-25 | B5: DC4 | C5: 44341 | D5: 3.8125999 | E5: 3.7964429 | F5: 5583.4354
A6: DC4 2022-02-09 | B6: DC4 | C6: 44601 | D6: 16.248008 | E6: 16.158182 | F6: 18752.764 | G6: 14301.435 | H6: 414.1972
A7: DC4 2020-11-03 | B7: DC4 | C7: 44138 | D7: 2.8250026 | E7: 2.818032 | F7: 3270.5343 | G7: 62.596494 | H7: 1.8129155
A8: DC4 2021-07-07 | B8: DC4 | C8: 44384 | D8: 19.506647 | E8: 19.432898 | F8: 38318.217 | G8: 58522.014 | H8: 1146.477
A9: DC4 2021-04-29 | B9: DC4 | C9: 44315 | D9: 2.7382336 | E9: 2.7266802 | F9: 3164.5138
A10: DC4 2021-08-03 | B10: DC4 | C10: 44411 | D10: 4.2464308 | E10: 4.2311405 | F10: 7107.239 | G10: 3107.3053 | H10: 68.24246
A11: DC4 2022-05-06 | B11: DC4 | C11: 44687 | D11: 3.9333745 | E11: 3.9073254 | F11: 4534.7397 | G11: 118.58691 | H11: 3.4345061
A12: DC4 2021-04-08 | B12: DC4 | C12: 44294 | D12: 3.5489247 | E12: 3.5361282 | F12: 4103.938
A13: DC4 2021-06-21 | B13: DC4 | C13: 44368 | D13: 2.8037858 | E13: 2.7917166 | F13: 4514.3044 | G13: 177.9384 | H13: 4.0175443
A14: DC4 2021-11-24 | B14: DC4 | C14: 44524 | D14: 10.824453 | E14: 10.777743 | F14: 12508.367 | G14: 1173.7995 | H14: 33.995504
A15: DC4 2021-07-19 | B15: DC4 | C15: 44396 | D15: 3.6853055 | E15: 3.6718057 | F15: 6344.9348 | G15: 964.77018 | H15: 20.758788
A16: DC4 2021-10-12 | B16: DC4 | C16: 44481 | D16: 3.1145379 | E16: 3.1035936 | F16: 4215.6262 | G16: 438.29116 | H16: 11.261478
A17: DC4 2020-08-10 | B17: DC4 | C17: 44053 | D17: 19.344305 | E17: 19.292772 | F17: 34281.098 | G17: 52075.142 | H17: 1098.2572
A18: DC4 2021-04-20 | B18: DC4 | C18: 44306 | D18: 2.6033284 | E18: 2.5907566 | F18: 3006.7644
A19: DC4 2020-04-24 | B19: DC4 | C19: 43945 | D19: 4.0971432 | E19: 4.0865744 | F19: 4742.7714 | G19: 74.419572 | H19: 2.1553347
A20: DC4 2020-11-18 | B20: DC4 | C20: 44153 | D20: 3.3647597 | E20: 3.3560801 | F20: 3894.9788 | G20: 62.70505 | H20: 1.8160594
A21: DC4 2021-09-01 | B21: DC4 | C21: 44440 | D21: 5.1393628 | E21: 5.1223235 | F21: 7815.1097 | G21: 4707.498 | H21: 110.92147
A22: DC4 2023-09-14 | B22: DC4 | C22: 45183 | D22: 4.8153912 | E22: 4.7898854 | F22: 6786.0552 | G22: 4763.8091 | H22: 118.59646
A23: DC4 2022-06-21 | B23: DC4 | C23: 44733 | D23: 3.1731601 | E23: 3.157526 | F23: 5105.8312 | G23: 693.90931 | H23: 15.667284
A24: DC4 2022-05-23 | B24: DC4 | C24: 44704 | D24: 4.9077929 | E24: 4.8817476 | F24: 6486.5912 | G24: 1231.9366 | H24: 32.182594
A25: DC4 2023-08-30 | B25: DC4 | C25: 45168 | D25: 3.7422709 | E25: 3.7270185 | F25: 5934.2572 | G25: 407.58053 | H25: 9.3070876
A26: DC4 2024-09-10 | B26: DC4 | C26: 45545 | D26: 4.4226838 | E26: 4.3959384 | F26: 6416.5808 | G26: 1946.1153 | H26: 47.383464
A27: DC4 2024-07-16 | B27: DC4 | C27: 45489 | D27: 9.1141726 | E27: 9.0680161 | F27: 16525.08 | G27: 4294.8862 | H27: 88.957949
A28: DC4 2021-05-14 | B28: DC4 | C28: 44330 | D28: 2.6372889 | E28: 2.6250147 | F28: 3751.8209 | G28: 90.532298 | H28: 2.2390836
A29: DC4 2021-05-04 | B29: DC4 | C29: 44320 | D29: 3.1214867 | E29: 3.108609 | F29: 3607.7703 | G29: 82.036004 | H29: 2.3759213
A30: DC4 2020-08-24 | B30: DC4 | C30: 44067 | D30: 21.47022 | E30: 21.404835 | F30: 32885.786 | G30: 56089.119 | H30: 1314.8345
... A38: DC4 2021-05-10 | B38: DC4 | C38: 44326 | D38: 2.3594896 | E38: 2.3483603 | F38: 2809.3925 | G38: 65.35918 | H38: 1.8493426
A39: DC4 2021-04-21 | B39: DC4 | C39: 44307 | D39: 2.698238 | E39: 2.6857816 | F39: 3117.0479
A40: DC4 2019-10-10 | B40: DC4 | C40: 43748 | D40: 4.2172448 | E40: 4.2042498 | F40: 6137.1123 | G40: 406.74657 | H40: 9.9029521
A41: DC4 2023-05-03 | B41: DC4 | C41: 45049 | D41: 2.6754507 | E41: 2.6573275 | F41: 3084.0248 | G41: 51.973275 | H41: 1.5052465
A42: DC4 2021-08-18 | B42: DC4 | C42: 44426 | D42: 3.5669141 | E42: 3.5555734 | F42: 6070.2313 | G42: 572.70927 | H42: 12.430882
A43: DC4 2019-04-21 | B43: DC4 | C43: 43576 | D43: 3.6875502 | E43: 3.6794054 | F43: 4270.2217 | G43: 91.155175 | H43: 2.6400301
A44: DC4 2021-03-17 | B44: DC4 | C44: 44272 | D44: 3.8623621 | E44: 3.8410094 | F44: 4457.7751
A45: DC4 2021-02-17 | B45: DC4 | C45: 44244 | D45: 3.9853667 | E45: 3.968169 | F45: 4605.3532
A46: DC4 2020-10-07 | B46: DC4 | C46: 44111 | D46: 4.8547005 | E46: 4.8411744 | F46: 7186.1347 | G46: 290.57903 | H46: 6.9872839
